Workbook

Sheet Read_Me
A1: IRD gene-specific allele-frequency cut-offs (BA1 / BS1 / PM2_Supporting) — Whiffin maximum-credible-AF method, Indian parameters
A2: Prepared for ARIDE-CAP variant curation · built 23-Sep-2026 · all thresholds are LIVE formulas driven by the 'Inputs' sheet
A4: WHAT THIS WORKBOOK DOES
A5: For each IRD gene it asks: 'Given how common IRD is in India, how much of it this gene causes, and how penetrant it is, what is the highest population allele frequency a pathogenic variant could credibly have?' (Whiffin et al., Genet Med 2017). Variants above that ceiling are too common to be pathogenic.
A7: SHEETS
A8: Inputs — all editable parameters (prevalence, penetrance, allelic shares, floor, inbreeding coefficient, data-source switch).
A9: Gene_Thresholds — one row per gene × inheritance mode (225 rows); BA1, BS1, PM2_Supporting cut-offs + comparison to published ClinGen specifications.
A10: Indian_Gene_Shares — within-phenotype gene shares from the Indian IRD literature (Hum Genomics 2026;20:42) → converted to each gene's share of ALL Indian IRD.
A11: Phenotype_Mix — share of each IRD phenotype among clinically reported Indian IRD cases (same source).
A12: ARIDE_Cohort — EMPTY input sheet: enter solved-family counts per gene from the ARIDE-CAP cohort; flip the switch on Inputs to use them instead of literature values.
A13: Published_Specs — existing gene-specific specifications (ClinGen VCEPs, ABCA4, Japan IRD) for sanity-checking.
A14: Methods — formulas and reasoning. References — full citations.
... A28: 5. Prevalence anchors are population-based RP prevalence in adults ≥40 y; total IRD prevalence is back-calculated using the RP share of the phenotype mix.

Sheet Inputs
A1: Model inputs (edit yellow cells only)
A3: 1. Indian IRD prevalence
A4: RP prevalence — Tamil Nadu (Chennai, ≥40 y) | B4: 0.0017 | C4: Sen P et al. Ophthalmic Epidemiol 2008;15(4):279-81 (0.17%)
A5: RP prevalence — Central India (CIEMS, ≥30 y) | B5: 0.0013 | C5: Nangia V et al. Acta Ophthalmol 2012;90(8):e649-50 (0.13%, ~1 in 750)
A6: RP prevalence — Andhra Pradesh (APEDS) | B6: 0.001 | C6: APEDS, as summarised in Front Genet 2022;13:858556 (~1 in 1,000)
A7: RP share of all IRD (from Phenotype_Mix) | B7: =INDEX(Phenotype_Mix!$D:$D,MATCH("RP",Phenotype_Mix!$A:$A,0)) -> 0.76928191 | C7: Converts RP prevalence into total IRD prevalence
A8: IRD prevalence — point estimate (P) | B8: =AVERAGE(B4:B6)/B7 -> 0.0017332181 | C8: Mean RP prevalence ÷ RP share. Used for PM2 (conservative direction).
A9: IRD prevalence — upper estimate (P_upper) | B9: =MAX(B4:B6)/B7 -> 0.0022098531 | C9: Highest RP prevalence ÷ RP share. Used for BS1 and BA1 (conservative direction).
A10: = 1 in … (point) | B10: =1/B8 -> 576.96144
A11: = 1 in … (upper) | B11: =1/B9 -> 452.51877
A13: 2. Penetrance
A14: Penetrance — autosomal recessive (biallelic) | B14: 1 | C14: Whiffin default for fully penetrant recessive disease. Lower it for genes with known hypomorphs → raises cut-offs.
A15: Penetrance — autosomal dominant | B15: 0.5 | C15: Conservative (as Whiffin 2017 used for HCM); AD IRD shows variable expressivity (e.g. PRPF31).
A16: Penetrance — X-linked (hemizygous males) | B16: 1
A18: 3. Allelic contribution & criterion spacing
A19: BA1 multiplier (BA1 = BS1 × this) | B19: 10 | C19: Both ClinGen retina VCEPs set BA1 = 10 × BS1 (RPE65: 8e-3 vs 8e-4; RS1: 2e-4 vs 2e-5).
A20: Allelic share for BS1 (default; per-gene override on Gene_Thresholds) | B20: 0.5 | C20: Whiffin 'maximum allelic contribution'. Founder-rich, consanguineous Indian cohorts → one allele can dominate; 0.5 is conservative.
A21: Allelic share for PM2_Supporting | B21: 0.05 | C21: A variant explaining ≤5% of the gene's pathogenic alleles counts as 'rare' (gives PM2 ≈ BS1/10, as in the RS1 VCEP).
A23: 4. Guard-rails
A24: Gene-contribution floor (min share of all IRD) | B24: 0.01 | C24: Applied when Indian data are missing or smaller. Raising it makes cut-offs more lenient (safer for BA1/BS1).
A25: Inbreeding coefficient F (applied to PM2 of AR genes only) | B25: 0 | C25: South Indian average F ≈ 0.01–0.02. F>0 lowers the PM2 cut-off (stricter, i.e. conservative). Not applied to BA1/BS1.
A26: BA1 cap (ACMG default) | B26: 0.05 | C26: BA1 never exceeds 5% (Richards et al. 2015).
A28: 5. Data source
A29: Gene-contribution source | B29: Indian literature | C29: Choose 'Indian literature' or 'ARIDE cohort'.
A30: Minimum ARIDE solved families before switch takes effect | B30: 50 | C30: Protects against tiny-sample shares.

Sheet Gene_Thresholds
A1: Whiffin-based allele-frequency cut-offs for IRD genes — Indian parameters
A2: Compare against gnomAD grpmax FAF95 (+ SAS / IndiGen / GenomeIndia); X-linked rows = hemizygous male AF. BA1/BS1: AF ≥ cut-off. PM2_Supporting: AF ≤ cut-off or absent. Columns V–X give the value to USE: the published ClinGen/expert specification where one exists, otherwise this workbook's calculation.
A4: Gene | B4: Inheritance | C4: Phenotype group | D4: Gene share of Indian IRD — literature | E4: Gene share — ARIDE cohort | F4: Gene share USED (g) | G4: g basis | H4: Penetrance — default | I4: Penetrance — override | J4: Penetrance used | K4: Allelic share BS1 — override | L4: Allelic share BS1 used | M4: Max credible total pathogenic AF, Q (upper P, F=0) | N4: Q (point P, with F) | O4: Calc BS1 (≥) | P4: Calc BA1 (≥) | Q4: Calc PM2_Sup (≤) | R4: Published BA1 | S4: Published BS1 | T4: Published PM2 | U4: Recommended source | V4: RECOMMENDED BA1 (≥) | W4: RECOMMENDED BS1 (≥) | X4: RECOMMENDED PM2_Sup (≤) | Y4: Calc vs published BS1 | Z4: Frequency metric to compare | AA4: Published specification (text) | AB4: Notes
A5: ABCA4 | B5: AR | C5: MD/STGD,CRD | D5: =SUMIF(Indian_Gene_Shares!$B$5:$B$47,A5,Indian_Gene_Shares!$G$5:$G$47) -> 0.10130897 | E5: =IFERROR(INDEX(ARIDE_Cohort!$C$6:$C$207,MATCH(A5,ARIDE_Cohort!$A$6:$A$207,0)),0) -> 0 | F5: =MAX(Inputs!$B$24,IF(AND(Inputs!$B$29="ARIDE cohort",ARIDE_Cohort!$B$3>=Inputs!$B$30),E5,D5)) -> 0.10130897 | G5: =IF(AND(Inputs!$B$29="ARIDE cohort",ARIDE_Cohort!$B$3>=Inputs!$B$30),IF(E5>Inputs!$B$24,"ARIDE cohort","Floor (ARIDE share below floor)"),IF(D5>Inputs!$B$24,"Indian literature",IF(D5>0,"Floor (Indian share below floor)","Floor (no Indian data)"))) -> Indian literature | H5: =IF(B5="AR",Inputs!$B$14,IF(B5="AD",Inputs!$B$15,Inputs!$B$16)) -> 1 | J5: =IF(I5="",H5,I5) -> 1 | L5: =IF(K5="",Inputs!$B$20,K5) -> 0.5 | M5: =IF(B5="AR",SQRT(Inputs!$B$9*F5/J5),IF(B5="AD",Inputs!$B$9*F5/(2*J5),2*Inputs!$B$9*F5/J5)) -> 0.014962551 | N5: =IF(B5="AR",IF(Inputs!$B$25=0,SQRT(Inputs!$B$8*F5/J5),(-Inputs!$B$25+SQRT(Inputs!$B$25^2+4*(1-Inputs!$B$25)*Inputs!$B$8*F5/J5))/(2*(1-Inputs!$B$25))),IF(B5="AD",Inputs!$B$8*F5/(2*J5),2*Inputs!$B$8*F5/J5)) -> 0.013251058 | O5: =MIN(Inputs!$B$26,M5*L5) -> 0.0074812756 | P5: =MIN(Inputs!$B$26,O5*Inputs!$B$19) -> 0.05 | Q5: =MIN(O5,N5*Inputs!$B$21) -> 0.00066255291 | S5: 0.0163 | T5: 0.0001 | U5: =IF(COUNT(R5:T5)>0,"Published spec (+calc where blank)","Calculated (this workbook)") -> Published spec (+calc where blank) | V5: =IF(R5="",MAX(P5,W5),R5) -> 0.05 | W5: =IF(S5="",O5,S5) -> 0.0163 | X5: =IF(T5="",Q5,T5) -> 0.0001 | Y5: =IF(S5="","",IF(O5<S5,"Calc STRICTER (lower)","Calc more lenient (higher)")) -> Calc STRICTER (lower) | Z5: =IF(B5="XL","Hemizygous male AF (grpmax)","grpmax FAF95; check SAS, IndiGen, GenomeIndia") -> grpmax FAF95; check SAS, IndiGen, GenomeIndia | AA5: Cornelis et al. 2023: BS1 >0.0163 any gnomAD pop; PM2_Sup <1e-4 | AB5: Hypomorphic alleles (e.g. c.5603A>T) exceed BS1 yet are pathogenic in trans with severe alleles — do not apply BS1 to them.
A6: ABHD12 | B6: AR | C6: USH-like (PHARC) | D6: =SUMIF(Indian_Gene_Shares!$B$5:$B$47,A6,Indian_Gene_Shares!$G$5:$G$47) -> 0 | E6: =IFERROR(INDEX(ARIDE_Cohort!$C$6:$C$207,MATCH(A6,ARIDE_Cohort!$A$6:$A$207,0)),0) -> 0 | F6: =MAX(Inputs!$B$24,IF(AND(Inputs!$B$29="ARIDE cohort",ARIDE_Cohort!$B$3>=Inputs!$B$30),E6,D6)) -> 0.01 | G6: =IF(AND(Inputs!$B$29="ARIDE cohort",ARIDE_Cohort!$B$3>=Inputs!$B$30),IF(E6>Inputs!$B$24,"ARIDE cohort","Floor (ARIDE share below floor)"),IF(D6>Inputs!$B$24,"Indian literature",IF(D6>0,"Floor (Indian share below floor)","Floor (no Indian data)"))) -> Floor (no Indian data) | H6: =IF(B6="AR",Inputs!$B$14,IF(B6="AD",Inputs!$B$15,Inputs!$B$16)) -> 1 | J6: =IF(I6="",H6,I6) -> 1 | L6: =IF(K6="",Inputs!$B$20,K6) -> 0.5 | M6: =IF(B6="AR",SQRT(Inputs!$B$9*F6/J6),IF(B6="AD",Inputs!$B$9*F6/(2*J6),2*Inputs!$B$9*F6/J6)) -> 0.0047009074 | N6: =IF(B6="AR",IF(Inputs!$B$25=0,SQRT(Inputs!$B$8*F6/J6),(-Inputs!$B$25+SQRT(Inputs!$B$25^2+4*(1-Inputs!$B$25)*Inputs!$B$8*F6/J6))/(2*(1-Inputs!$B$25))),IF(B6="AD",Inputs!$B$8*F6/(2*J6),2*Inputs!$B$8*F6/J6)) -> 0.0041631936 | O6: =MIN(Inputs!$B$26,M6*L6) -> 0.0023504537 | P6: =MIN(Inputs!$B$26,O6*Inputs!$B$19) -> 0.023504537 | Q6: =MIN(O6,N6*Inputs!$B$21) -> 0.00020815968 | U6: =IF(COUNT(R6:T6)>0,"Published spec (+calc where blank)","Calculated (this workbook)") -> Calculated (this workbook) | V6: =IF(R6="",MAX(P6,W6),R6) -> 0.023504537 | W6: =IF(S6="",O6,S6) -> 0.0023504537 | X6: =IF(T6="",Q6,T6) -> 0.00020815968 | Y6: =IF(S6="","",IF(O6<S6,"Calc STRICTER (lower)","Calc more lenient (higher)")) | Z6: =IF(B6="XL","Hemizygous male AF (grpmax)","grpmax FAF95; check SAS, IndiGen, GenomeIndia") -> grpmax FAF95; check SAS, IndiGen, GenomeIndia
A7: ADAM9 | B7: AR | C7: CRD | D7: =SUMIF(Indian_Gene_Shares!$B$5:$B$47,A7,Indian_Gene_Shares!$G$5:$G$47) -> 0 | E7: =IFERROR(INDEX(ARIDE_Cohort!$C$6:$C$207,MATCH(A7,ARIDE_Cohort!$A$6:$A$207,0)),0) -> 0 | F7: =MAX(Inputs!$B$24,IF(AND(Inputs!$B$29="ARIDE cohort",ARIDE_Cohort!$B$3>=Inputs!$B$30),E7,D7)) -> 0.01 | G7: =IF(AND(Inputs!$B$29="ARIDE cohort",ARIDE_Cohort!$B$3>=Inputs!$B$30),IF(E7>Inputs!$B$24,"ARIDE cohort","Floor (ARIDE share below floor)"),IF(D7>Inputs!$B$24,"Indian literature",IF(D7>0,"Floor (Indian share below floor)","Floor (no Indian data)"))) -> Floor (no Indian data) | H7: =IF(B7="AR",Inputs!$B$14,IF(B7="AD",Inputs!$B$15,Inputs!$B$16)) -> 1 | J7: =IF(I7="",H7,I7) -> 1 | L7: =IF(K7="",Inputs!$B$20,K7) -> 0.5 | M7: =IF(B7="AR",SQRT(Inputs!$B$9*F7/J7),IF(B7="AD",Inputs!$B$9*F7/(2*J7),2*Inputs!$B$9*F7/J7)) -> 0.0047009074 | N7: =IF(B7="AR",IF(Inputs!$B$25=0,SQRT(Inputs!$B$8*F7/J7),(-Inputs!$B$25+SQRT(Inputs!$B$25^2+4*(1-Inputs!$B$25)*Inputs!$B$8*F7/J7))/(2*(1-Inputs!$B$25))),IF(B7="AD",Inputs!$B$8*F7/(2*J7),2*Inputs!$B$8*F7/J7)) -> 0.0041631936 | O7: =MIN(Inputs!$B$26,M7*L7) -> 0.0023504537 | P7: =MIN(Inputs!$B$26,O7*Inputs!$B$19) -> 0.023504537 | Q7: =MIN(O7,N7*Inputs!$B$21) -> 0.00020815968 | U7: =IF(COUNT(R7:T7)>0,"Published spec (+calc where blank)","Calculated (this workbook)") -> Calculated (this workbook) | V7: =IF(R7="",MAX(P7,W7),R7) -> 0.023504537 | W7: =IF(S7="",O7,S7) -> 0.0023504537 | X7: =IF(T7="",Q7,T7) -> 0.00020815968 | Y7: =IF(S7="","",IF(O7<S7,"Calc STRICTER (lower)","Calc more lenient (higher)")) | Z7: =IF(B7="XL","Hemizygous male AF (grpmax)","grpmax FAF95; check SAS, IndiGen, GenomeIndia") -> grpmax FAF95; check SAS, IndiGen, GenomeIndia
A8: ADGRA3 | B8: AR | C8: RP | D8: =SUMIF(Indian_Gene_Shares!$B$5:$B$47,A8,Indian_Gene_Shares!$G$5:$G$47) -> 0 | E8: =IFERROR(INDEX(ARIDE_Cohort!$C$6:$C$207,MATCH(A8,ARIDE_Cohort!$A$6:$A$207,0)),0) -> 0 | F8: =MAX(Inputs!$B$24,IF(AND(Inputs!$B$29="ARIDE cohort",ARIDE_Cohort!$B$3>=Inputs!$B$30),E8,D8)) -> 0.01 | G8: =IF(AND(Inputs!$B$29="ARIDE cohort",ARIDE_Cohort!$B$3>=Inputs!$B$30),IF(E8>Inputs!$B$24,"ARIDE cohort","Floor (ARIDE share below floor)"),IF(D8>Inputs!$B$24,"Indian literature",IF(D8>0,"Floor (Indian share below floor)","Floor (no Indian data)"))) -> Floor (no Indian data) | H8: =IF(B8="AR",Inputs!$B$14,IF(B8="AD",Inputs!$B$15,Inputs!$B$16)) -> 1 | J8: =IF(I8="",H8,I8) -> 1 | L8: =IF(K8="",Inputs!$B$20,K8) -> 0.5 | M8: =IF(B8="AR",SQRT(Inputs!$B$9*F8/J8),IF(B8="AD",Inputs!$B$9*F8/(2*J8),2*Inputs!$B$9*F8/J8)) -> 0.0047009074 | N8: =IF(B8="AR",IF(Inputs!$B$25=0,SQRT(Inputs!$B$8*F8/J8),(-Inputs!$B$25+SQRT(Inputs!$B$25^2+4*(1-Inputs!$B$25)*Inputs!$B$8*F8/J8))/(2*(1-Inputs!$B$25))),IF(B8="AD",Inputs!$B$8*F8/(2*J8),2*Inputs!$B$8*F8/J8)) -> 0.0041631936 | O8: =MIN(Inputs!$B$26,M8*L8) -> 0.0023504537 | P8: =MIN(Inputs!$B$26,O8*Inputs!$B$19) -> 0.023504537 | Q8: =MIN(O8,N8*Inputs!$B$21) -> 0.00020815968 | U8: =IF(COUNT(R8:T8)>0,"Published spec (+calc where blank)","Calculated (this workbook)") -> Calculated (this workbook) | V8: =IF(R8="",MAX(P8,W8),R8) -> 0.023504537 | W8: =IF(S8="",O8,S8) -> 0.0023504537 | X8: =IF(T8="",Q8,T8) -> 0.00020815968 | Y8: =IF(S8="","",IF(O8<S8,"Calc STRICTER (lower)","Calc more lenient (higher)")) | Z8: =IF(B8="XL","Hemizygous male AF (grpmax)","grpmax FAF95; check SAS, IndiGen, GenomeIndia") -> grpmax FAF95; check SAS, IndiGen, GenomeIndia
A9: ADGRV1 | B9: AR | C9: USH2 | D9: =SUMIF(Indian_Gene_Shares!$B$5:$B$47,A9,Indian_Gene_Shares!$G$5:$G$47) -> 0 | E9: =IFERROR(INDEX(ARIDE_Cohort!$C$6:$C$207,MATCH(A9,ARIDE_Cohort!$A$6:$A$207,0)),0) -> 0 | F9: =MAX(Inputs!$B$24,IF(AND(Inputs!$B$29="ARIDE cohort",ARIDE_Cohort!$B$3>=Inputs!$B$30),E9,D9)) -> 0.01 | G9: =IF(AND(Inputs!$B$29="ARIDE cohort",ARIDE_Cohort!$B$3>=Inputs!$B$30),IF(E9>Inputs!$B$24,"ARIDE cohort","Floor (ARIDE share below floor)"),IF(D9>Inputs!$B$24,"Indian literature",IF(D9>0,"Floor (Indian share below floor)","Floor (no Indian data)"))) -> Floor (no Indian data) | H9: =IF(B9="AR",Inputs!$B$14,IF(B9="AD",Inputs!$B$15,Inputs!$B$16)) -> 1 | J9: =IF(I9="",H9,I9) -> 1 | L9: =IF(K9="",Inputs!$B$20,K9) -> 0.5 | M9: =IF(B9="AR",SQRT(Inputs!$B$9*F9/J9),IF(B9="AD",Inputs!$B$9*F9/(2*J9),2*Inputs!$B$9*F9/J9)) -> 0.0047009074 | N9: =IF(B9="AR",IF(Inputs!$B$25=0,SQRT(Inputs!$B$8*F9/J9),(-Inputs!$B$25+SQRT(Inputs!$B$25^2+4*(1-Inputs!$B$25)*Inputs!$B$8*F9/J9))/(2*(1-Inputs!$B$25))),IF(B9="AD",Inputs!$B$8*F9/(2*J9),2*Inputs!$B$8*F9/J9)) -> 0.0041631936 | O9: =MIN(Inputs!$B$26,M9*L9) -> 0.0023504537 | P9: =MIN(Inputs!$B$26,O9*Inputs!$B$19) -> 0.023504537 | Q9: =MIN(O9,N9*Inputs!$B$21) -> 0.00020815968 | U9: =IF(COUNT(R9:T9)>0,"Published spec (+calc where blank)","Calculated (this workbook)") -> Calculated (this workbook) | V9: =IF(R9="",MAX(P9,W9),R9) -> 0.023504537 | W9: =IF(S9="",O9,S9) -> 0.0023504537 | X9: =IF(T9="",Q9,T9) -> 0.00020815968 | Y9: =IF(S9="","",IF(O9<S9,"Calc STRICTER (lower)","Calc more lenient (higher)")) | Z9: =IF(B9="XL","Hemizygous male AF (grpmax)","grpmax FAF95; check SAS, IndiGen, GenomeIndia") -> grpmax FAF95; check SAS, IndiGen, GenomeIndia
A10: ADIPOR1 | B10: AR | C10: RP | D10: =SUMIF(Indian_Gene_Shares!$B$5:$B$47,A10,Indian_Gene_Shares!$G$5:$G$47) -> 0 | E10: =IFERROR(INDEX(ARIDE_Cohort!$C$6:$C$207,MATCH(A10,ARIDE_Cohort!$A$6:$A$207,0)),0) -> 0 | F10: =MAX(Inputs!$B$24,IF(AND(Inputs!$B$29="ARIDE cohort",ARIDE_Cohort!$B$3>=Inputs!$B$30),E10,D10)) -> 0.01 | G10: =IF(AND(Inputs!$B$29="ARIDE cohort",ARIDE_Cohort!$B$3>=Inputs!$B$30),IF(E10>Inputs!$B$24,"ARIDE cohort","Floor (ARIDE share below floor)"),IF(D10>Inputs!$B$24,"Indian literature",IF(D10>0,"Floor (Indian share below floor)","Floor (no Indian data)"))) -> Floor (no Indian data) | H10: =IF(B10="AR",Inputs!$B$14,IF(B10="AD",Inputs!$B$15,Inputs!$B$16)) -> 1 | J10: =IF(I10="",H10,I10) -> 1 | L10: =IF(K10="",Inputs!$B$20,K10) -> 0.5 | M10: =IF(B10="AR",SQRT(Inputs!$B$9*F10/J10),IF(B10="AD",Inputs!$B$9*F10/(2*J10),2*Inputs!$B$9*F10/J10)) -> 0.0047009074 | N10: =IF(B10="AR",IF(Inputs!$B$25=0,SQRT(Inputs!$B$8*F10/J10),(-Inputs!$B$25+SQRT(Inputs!$B$25^2+4*(1-Inputs!$B$25)*Inputs!$B$8*F10/J10))/(2*(1-Inputs!$B$25))),IF(B10="AD",Inputs!$B$8*F10/(2*J10),2*Inputs!$B$8*F10/J10)) -> 0.0041631936 | O10: =MIN(Inputs!$B$26,M10*L10) -> 0.0023504537 | P10: =MIN(Inputs!$B$26,O10*Inputs!$B$19) -> 0.023504537 | Q10: =MIN(O10,N10*Inputs!$B$21) -> 0.00020815968 | U10: =IF(COUNT(R10:T10)>0,"Published spec (+calc where blank)","Calculated (this workbook)") -> Calculated (this workbook) | V10: =IF(R10="",MAX(P10,W10),R10) -> 0.023504537 | W10: =IF(S10="",O10,S10) -> 0.0023504537 | X10: =IF(T10="",Q10,T10) -> 0.00020815968 | Y10: =IF(S10="","",IF(O10<S10,"Calc STRICTER (lower)","Calc more lenient (higher)")) | Z10: =IF(B10="XL","Hemizygous male AF (grpmax)","grpmax FAF95; check SAS, IndiGen, GenomeIndia") -> grpmax FAF95; check SAS, IndiGen, GenomeIndia
A11: ADIPOR1 | B11: AD | C11: RP | D11: =SUMIF(Indian_Gene_Shares!$B$5:$B$47,A11,Indian_Gene_Shares!$G$5:$G$47) -> 0 | E11: =IFERROR(INDEX(ARIDE_Cohort!$C$6:$C$207,MATCH(A11,ARIDE_Cohort!$A$6:$A$207,0)),0) -> 0 | F11: =MAX(Inputs!$B$24,IF(AND(Inputs!$B$29="ARIDE cohort",ARIDE_Cohort!$B$3>=Inputs!$B$30),E11,D11)) -> 0.01 | G11: =IF(AND(Inputs!$B$29="ARIDE cohort",ARIDE_Cohort!$B$3>=Inputs!$B$30),IF(E11>Inputs!$B$24,"ARIDE cohort","Floor (ARIDE share below floor)"),IF(D11>Inputs!$B$24,"Indian literature",IF(D11>0,"Floor (Indian share below floor)","Floor (no Indian data)"))) -> Floor (no Indian data) | H11: =IF(B11="AR",Inputs!$B$14,IF(B11="AD",Inputs!$B$15,Inputs!$B$16)) -> 0.5 | J11: =IF(I11="",H11,I11) -> 0.5 | L11: =IF(K11="",Inputs!$B$20,K11) -> 0.5 | M11: =IF(B11="AR",SQRT(Inputs!$B$9*F11/J11),IF(B11="AD",Inputs!$B$9*F11/(2*J11),2*Inputs!$B$9*F11/J11)) -> 2.2098531e-05 | N11: =IF(B11="AR",IF(Inputs!$B$25=0,SQRT(Inputs!$B$8*F11/J11),(-Inputs!$B$25+SQRT(Inputs!$B$25^2+4*(1-Inputs!$B$25)*Inputs!$B$8*F11/J11))/(2*(1-Inputs!$B$25))),IF(B11="AD",Inputs!$B$8*F11/(2*J11),2*Inputs!$B$8*F11/J11)) -> 1.7332181e-05 | O11: =MIN(Inputs!$B$26,M11*L11) -> 1.1049265e-05 | P11: =MIN(Inputs!$B$26,O11*Inputs!$B$19) -> 0.00011049265 | Q11: =MIN(O11,N11*Inputs!$B$21) -> 8.6660905e-07 | U11: =IF(COUNT(R11:T11)>0,"Published spec (+calc where blank)","Calculated (this workbook)") -> Calculated (this workbook) | V11: =IF(R11="",MAX(P11,W11),R11) -> 0.00011049265 | W11: =IF(S11="",O11,S11) -> 1.1049265e-05 | X11: =IF(T11="",Q11,T11) -> 8.6660905e-07 | Y11: =IF(S11="","",IF(O11<S11,"Calc STRICTER (lower)","Calc more lenient (higher)")) | Z11: =IF(B11="XL","Hemizygous male AF (grpmax)","grpmax FAF95; check SAS, IndiGen, GenomeIndia") -> grpmax FAF95; check SAS, IndiGen, GenomeIndia
A12: AGBL5 | B12: AR | C12: RP | D12: =SUMIF(Indian_Gene_Shares!$B$5:$B$47,A12,Indian_Gene_Shares!$G$5:$G$47) -> 0 | E12: =IFERROR(INDEX(ARIDE_Cohort!$C$6:$C$207,MATCH(A12,ARIDE_Cohort!$A$6:$A$207,0)),0) -> 0 | F12: =MAX(Inputs!$B$24,IF(AND(Inputs!$B$29="ARIDE cohort",ARIDE_Cohort!$B$3>=Inputs!$B$30),E12,D12)) -> 0.01 | G12: =IF(AND(Inputs!$B$29="ARIDE cohort",ARIDE_Cohort!$B$3>=Inputs!$B$30),IF(E12>Inputs!$B$24,"ARIDE cohort","Floor (ARIDE share below floor)"),IF(D12>Inputs!$B$24,"Indian literature",IF(D12>0,"Floor (Indian share below floor)","Floor (no Indian data)"))) -> Floor (no Indian data) | H12: =IF(B12="AR",Inputs!$B$14,IF(B12="AD",Inputs!$B$15,Inputs!$B$16)) -> 1 | J12: =IF(I12="",H12,I12) -> 1 | L12: =IF(K12="",Inputs!$B$20,K12) -> 0.5 | M12: =IF(B12="AR",SQRT(Inputs!$B$9*F12/J12),IF(B12="AD",Inputs!$B$9*F12/(2*J12),2*Inputs!$B$9*F12/J12)) -> 0.0047009074 | N12: =IF(B12="AR",IF(Inputs!$B$25=0,SQRT(Inputs!$B$8*F12/J12),(-Inputs!$B$25+SQRT(Inputs!$B$25^2+4*(1-Inputs!$B$25)*Inputs!$B$8*F12/J12))/(2*(1-Inputs!$B$25))),IF(B12="AD",Inputs!$B$8*F12/(2*J12),2*Inputs!$B$8*F12/J12)) -> 0.0041631936 | O12: =MIN(Inputs!$B$26,M12*L12) -> 0.0023504537 | P12: =MIN(Inputs!$B$26,O12*Inputs!$B$19) -> 0.023504537 | Q12: =MIN(O12,N12*Inputs!$B$21) -> 0.00020815968 | U12: =IF(COUNT(R12:T12)>0,"Published spec (+calc where blank)","Calculated (this workbook)") -> Calculated (this workbook) | V12: =IF(R12="",MAX(P12,W12),R12) -> 0.023504537 | W12: =IF(S12="",O12,S12) -> 0.0023504537 | X12: =IF(T12="",Q12,T12) -> 0.00020815968 | Y12: =IF(S12="","",IF(O12<S12,"Calc STRICTER (lower)","Calc more lenient (higher)")) | Z12: =IF(B12="XL","Hemizygous male AF (grpmax)","grpmax FAF95; check SAS, IndiGen, GenomeIndia") -> grpmax FAF95; check SAS, IndiGen, GenomeIndia
A13: AHI1 | B13: AR | C13: JS | D13: =SUMIF(Indian_Gene_Shares!$B$5:$B$47,A13,Indian_Gene_Shares!$G$5:$G$47) -> 0.00044370251 | E13: =IFERROR(INDEX(ARIDE_Cohort!$C$6:$C$207,MATCH(A13,ARIDE_Cohort!$A$6:$A$207,0)),0) -> 0 | F13: =MAX(Inputs!$B$24,IF(AND(Inputs!$B$29="ARIDE cohort",ARIDE_Cohort!$B$3>=Inputs!$B$30),E13,D13)) -> 0.01 | G13: =IF(AND(Inputs!$B$29="ARIDE cohort",ARIDE_Cohort!$B$3>=Inputs!$B$30),IF(E13>Inputs!$B$24,"ARIDE cohort","Floor (ARIDE share below floor)"),IF(D13>Inputs!$B$24,"Indian literature",IF(D13>0,"Floor (Indian share below floor)","Floor (no Indian data)"))) -> Floor (Indian share below floor) | H13: =IF(B13="AR",Inputs!$B$14,IF(B13="AD",Inputs!$B$15,Inputs!$B$16)) -> 1 | J13: =IF(I13="",H13,I13) -> 1 | L13: =IF(K13="",Inputs!$B$20,K13) -> 0.5 | M13: =IF(B13="AR",SQRT(Inputs!$B$9*F13/J13),IF(B13="AD",Inputs!$B$9*F13/(2*J13),2*Inputs!$B$9*F13/J13)) -> 0.0047009074 | N13: =IF(B13="AR",IF(Inputs!$B$25=0,SQRT(Inputs!$B$8*F13/J13),(-Inputs!$B$25+SQRT(Inputs!$B$25^2+4*(1-Inputs!$B$25)*Inputs!$B$8*F13/J13))/(2*(1-Inputs!$B$25))),IF(B13="AD",Inputs!$B$8*F13/(2*J13),2*Inputs!$B$8*F13/J13)) -> 0.0041631936 | O13: =MIN(Inputs!$B$26,M13*L13) -> 0.0023504537 | P13: =MIN(Inputs!$B$26,O13*Inputs!$B$19) -> 0.023504537 | Q13: =MIN(O13,N13*Inputs!$B$21) -> 0.00020815968 | U13: =IF(COUNT(R13:T13)>0,"Published spec (+calc where blank)","Calculated (this workbook)") -> Calculated (this workbook) | V13: =IF(R13="",MAX(P13,W13),R13) -> 0.023504537 | W13: =IF(S13="",O13,S13) -> 0.0023504537 | X13: =IF(T13="",Q13,T13) -> 0.00020815968 | Y13: =IF(S13="","",IF(O13<S13,"Calc STRICTER (lower)","Calc more lenient (higher)")) | Z13: =IF(B13="XL","Hemizygous male AF (grpmax)","grpmax FAF95; check SAS, IndiGen, GenomeIndia") -> grpmax FAF95; check SAS, IndiGen, GenomeIndia
A14: AHR | B14: AR | C14: RP | D14: =SUMIF(Indian_Gene_Shares!$B$5:$B$47,A14,Indian_Gene_Shares!$G$5:$G$47) -> 0 | E14: =IFERROR(INDEX(ARIDE_Cohort!$C$6:$C$207,MATCH(A14,ARIDE_Cohort!$A$6:$A$207,0)),0) -> 0 | F14: =MAX(Inputs!$B$24,IF(AND(Inputs!$B$29="ARIDE cohort",ARIDE_Cohort!$B$3>=Inputs!$B$30),E14,D14)) -> 0.01 | G14: =IF(AND(Inputs!$B$29="ARIDE cohort",ARIDE_Cohort!$B$3>=Inputs!$B$30),IF(E14>Inputs!$B$24,"ARIDE cohort","Floor (ARIDE share below floor)"),IF(D14>Inputs!$B$24,"Indian literature",IF(D14>0,"Floor (Indian share below floor)","Floor (no Indian data)"))) -> Floor (no Indian data) | H14: =IF(B14="AR",Inputs!$B$14,IF(B14="AD",Inputs!$B$15,Inputs!$B$16)) -> 1 | J14: =IF(I14="",H14,I14) -> 1 | L14: =IF(K14="",Inputs!$B$20,K14) -> 0.5 | M14: =IF(B14="AR",SQRT(Inputs!$B$9*F14/J14),IF(B14="AD",Inputs!$B$9*F14/(2*J14),2*Inputs!$B$9*F14/J14)) -> 0.0047009074 | N14: =IF(B14="AR",IF(Inputs!$B$25=0,SQRT(Inputs!$B$8*F14/J14),(-Inputs!$B$25+SQRT(Inputs!$B$25^2+4*(1-Inputs!$B$25)*Inputs!$B$8*F14/J14))/(2*(1-Inputs!$B$25))),IF(B14="AD",Inputs!$B$8*F14/(2*J14),2*Inputs!$B$8*F14/J14)) -> 0.0041631936 | O14: =MIN(Inputs!$B$26,M14*L14) -> 0.0023504537 | P14: =MIN(Inputs!$B$26,O14*Inputs!$B$19) -> 0.023504537 | Q14: =MIN(O14,N14*Inputs!$B$21) -> 0.00020815968 | U14: =IF(COUNT(R14:T14)>0,"Published spec (+calc where blank)","Calculated (this workbook)") -> Calculated (this workbook) | V14: =IF(R14="",MAX(P14,W14),R14) -> 0.023504537 | W14: =IF(S14="",O14,S14) -> 0.0023504537 | X14: =IF(T14="",Q14,T14) -> 0.00020815968 | Y14: =IF(S14="","",IF(O14<S14,"Calc STRICTER (lower)","Calc more lenient (higher)")) | Z14: =IF(B14="XL","Hemizygous male AF (grpmax)","grpmax FAF95; check SAS, IndiGen, GenomeIndia") -> grpmax FAF95; check SAS, IndiGen, GenomeIndia
A15: AIPL1 | B15: AR | C15: LCA | D15: =SUMIF(Indian_Gene_Shares!$B$5:$B$47,A15,Indian_Gene_Shares!$G$5:$G$47) -> 0.00083559081 | E15: =IFERROR(INDEX(ARIDE_Cohort!$C$6:$C$207,MATCH(A15,ARIDE_Cohort!$A$6:$A$207,0)),0) -> 0 | F15: =MAX(Inputs!$B$24,IF(AND(Inputs!$B$29="ARIDE cohort",ARIDE_Cohort!$B$3>=Inputs!$B$30),E15,D15)) -> 0.01 | G15: =IF(AND(Inputs!$B$29="ARIDE cohort",ARIDE_Cohort!$B$3>=Inputs!$B$30),IF(E15>Inputs!$B$24,"ARIDE cohort","Floor (ARIDE share below floor)"),IF(D15>Inputs!$B$24,"Indian literature",IF(D15>0,"Floor (Indian share below floor)","Floor (no Indian data)"))) -> Floor (Indian share below floor) | H15: =IF(B15="AR",Inputs!$B$14,IF(B15="AD",Inputs!$B$15,Inputs!$B$16)) -> 1 | J15: =IF(I15="",H15,I15) -> 1 | L15: =IF(K15="",Inputs!$B$20,K15) -> 0.5 | M15: =IF(B15="AR",SQRT(Inputs!$B$9*F15/J15),IF(B15="AD",Inputs!$B$9*F15/(2*J15),2*Inputs!$B$9*F15/J15)) -> 0.0047009074 | N15: =IF(B15="AR",IF(Inputs!$B$25=0,SQRT(Inputs!$B$8*F15/J15),(-Inputs!$B$25+SQRT(Inputs!$B$25^2+4*(1-Inputs!$B$25)*Inputs!$B$8*F15/J15))/(2*(1-Inputs!$B$25))),IF(B15="AD",Inputs!$B$8*F15/(2*J15),2*Inputs!$B$8*F15/J15)) -> 0.0041631936 | O15: =MIN(Inputs!$B$26,M15*L15) -> 0.0023504537 | P15: =MIN(Inputs!$B$26,O15*Inputs!$B$19) -> 0.023504537 | Q15: =MIN(O15,N15*Inputs!$B$21) -> 0.00020815968 | U15: =IF(COUNT(R15:T15)>0,"Published spec (+calc where blank)","Calculated (this workbook)") -> Calculated (this workbook) | V15: =IF(R15="",MAX(P15,W15),R15) -> 0.023504537 | W15: =IF(S15="",O15,S15) -> 0.0023504537 | X15: =IF(T15="",Q15,T15) -> 0.00020815968 | Y15: =IF(S15="","",IF(O15<S15,"Calc STRICTER (lower)","Calc more lenient (higher)")) | Z15: =IF(B15="XL","Hemizygous male AF (grpmax)","grpmax FAF95; check SAS, IndiGen, GenomeIndia") -> grpmax FAF95; check SAS, IndiGen, GenomeIndia
A16: AIPL1 | B16: AD | C16: CRD | D16: =SUMIF(Indian_Gene_Shares!$B$5:$B$47,A16,Indian_Gene_Shares!$G$5:$G$47) -> 0.00083559081 | E16: =IFERROR(INDEX(ARIDE_Cohort!$C$6:$C$207,MATCH(A16,ARIDE_Cohort!$A$6:$A$207,0)),0) -> 0 | F16: =MAX(Inputs!$B$24,IF(AND(Inputs!$B$29="ARIDE cohort",ARIDE_Cohort!$B$3>=Inputs!$B$30),E16,D16)) -> 0.01 | G16: =IF(AND(Inputs!$B$29="ARIDE cohort",ARIDE_Cohort!$B$3>=Inputs!$B$30),IF(E16>Inputs!$B$24,"ARIDE cohort","Floor (ARIDE share below floor)"),IF(D16>Inputs!$B$24,"Indian literature",IF(D16>0,"Floor (Indian share below floor)","Floor (no Indian data)"))) -> Floor (Indian share below floor) | H16: =IF(B16="AR",Inputs!$B$14,IF(B16="AD",Inputs!$B$15,Inputs!$B$16)) -> 0.5 | J16: =IF(I16="",H16,I16) -> 0.5 | L16: =IF(K16="",Inputs!$B$20,K16) -> 0.5 | M16: =IF(B16="AR",SQRT(Inputs!$B$9*F16/J16),IF(B16="AD",Inputs!$B$9*F16/(2*J16),2*Inputs!$B$9*F16/J16)) -> 2.2098531e-05 | N16: =IF(B16="AR",IF(Inputs!$B$25=0,SQRT(Inputs!$B$8*F16/J16),(-Inputs!$B$25+SQRT(Inputs!$B$25^2+4*(1-Inputs!$B$25)*Inputs!$B$8*F16/J16))/(2*(1-Inputs!$B$25))),IF(B16="AD",Inputs!$B$8*F16/(2*J16),2*Inputs!$B$8*F16/J16)) -> 1.7332181e-05 | O16: =MIN(Inputs!$B$26,M16*L16) -> 1.1049265e-05 | P16: =MIN(Inputs!$B$26,O16*Inputs!$B$19) -> 0.00011049265 | Q16: =MIN(O16,N16*Inputs!$B$21) -> 8.6660905e-07 | U16: =IF(COUNT(R16:T16)>0,"Published spec (+calc where blank)","Calculated (this workbook)") -> Calculated (this workbook) | V16: =IF(R16="",MAX(P16,W16),R16) -> 0.00011049265 | W16: =IF(S16="",O16,S16) -> 1.1049265e-05 | X16: =IF(T16="",Q16,T16) -> 8.6660905e-07 | Y16: =IF(S16="","",IF(O16<S16,"Calc STRICTER (lower)","Calc more lenient (higher)")) | Z16: =IF(B16="XL","Hemizygous male AF (grpmax)","grpmax FAF95; check SAS, IndiGen, GenomeIndia") -> grpmax FAF95; check SAS, IndiGen, GenomeIndia
A17: ALMS1 | B17: AR | C17: Alstrom | D17: =SUMIF(Indian_Gene_Shares!$B$5:$B$47,A17,Indian_Gene_Shares!$G$5:$G$47) -> 0.00042743161 | E17: =IFERROR(INDEX(ARIDE_Cohort!$C$6:$C$207,MATCH(A17,ARIDE_Cohort!$A$6:$A$207,0)),0) -> 0 | F17: =MAX(Inputs!$B$24,IF(AND(Inputs!$B$29="ARIDE cohort",ARIDE_Cohort!$B$3>=Inputs!$B$30),E17,D17)) -> 0.01 | G17: =IF(AND(Inputs!$B$29="ARIDE cohort",ARIDE_Cohort!$B$3>=Inputs!$B$30),IF(E17>Inputs!$B$24,"ARIDE cohort","Floor (ARIDE share below floor)"),IF(D17>Inputs!$B$24,"Indian literature",IF(D17>0,"Floor (Indian share below floor)","Floor (no Indian data)"))) -> Floor (Indian share below floor) | H17: =IF(B17="AR",Inputs!$B$14,IF(B17="AD",Inputs!$B$15,Inputs!$B$16)) -> 1 | J17: =IF(I17="",H17,I17) -> 1 | L17: =IF(K17="",Inputs!$B$20,K17) -> 0.5 | M17: =IF(B17="AR",SQRT(Inputs!$B$9*F17/J17),IF(B17="AD",Inputs!$B$9*F17/(2*J17),2*Inputs!$B$9*F17/J17)) -> 0.0047009074 | N17: =IF(B17="AR",IF(Inputs!$B$25=0,SQRT(Inputs!$B$8*F17/J17),(-Inputs!$B$25+SQRT(Inputs!$B$25^2+4*(1-Inputs!$B$25)*Inputs!$B$8*F17/J17))/(2*(1-Inputs!$B$25))),IF(B17="AD",Inputs!$B$8*F17/(2*J17),2*Inputs!$B$8*F17/J17)) -> 0.0041631936 | O17: =MIN(Inputs!$B$26,M17*L17) -> 0.0023504537 | P17: =MIN(Inputs!$B$26,O17*Inputs!$B$19) -> 0.023504537 | Q17: =MIN(O17,N17*Inputs!$B$21) -> 0.00020815968 | U17: =IF(COUNT(R17:T17)>0,"Published spec (+calc where blank)","Calculated (this workbook)") -> Calculated (this workbook) | V17: =IF(R17="",MAX(P17,W17),R17) -> 0.023504537 | W17: =IF(S17="",O17,S17) -> 0.0023504537 | X17: =IF(T17="",Q17,T17) -> 0.00020815968 | Y17: =IF(S17="","",IF(O17<S17,"Calc STRICTER (lower)","Calc more lenient (higher)")) | Z17: =IF(B17="XL","Hemizygous male AF (grpmax)","grpmax FAF95; check SAS, IndiGen, GenomeIndia") -> grpmax FAF95; check SAS, IndiGen, GenomeIndia
... A42: CC2D2A | B42: AR | C42: JS/RP | D42: =SUMIF(Indian_Gene_Shares!$B$5:$B$47,A42,Indian_Gene_Shares!$G$5:$G$47) -> 0.00044370251 | E42: =IFERROR(INDEX(ARIDE_Cohort!$C$6:$C$207,MATCH(A42,ARIDE_Cohort!$A$6:$A$207,0)),0) -> 0 | F42: =MAX(Inputs!$B$24,IF(AND(Inputs!$B$29="ARIDE cohort",ARIDE_Cohort!$B$3>=Inputs!$B$30),E42,D42)) -> 0.01 | G42: =IF(AND(Inputs!$B$29="ARIDE cohort",ARIDE_Cohort!$B$3>=Inputs!$B$30),IF(E42>Inputs!$B$24,"ARIDE cohort","Floor (ARIDE share below floor)"),IF(D42>Inputs!$B$24,"Indian literature",IF(D42>0,"Floor (Indian share below floor)","Floor (no Indian data)"))) -> Floor (Indian share below floor) | H42: =IF(B42="AR",Inputs!$B$14,IF(B42="AD",Inputs!$B$15,Inputs!$B$16)) -> 1 | J42: =IF(I42="",H42,I42) -> 1 | L42: =IF(K42="",Inputs!$B$20,K42) -> 0.5 | M42: =IF(B42="AR",SQRT(Inputs!$B$9*F42/J42),IF(B42="AD",Inputs!$B$9*F42/(2*J42),2*Inputs!$B$9*F42/J42)) -> 0.0047009074 | N42: =IF(B42="AR",IF(Inputs!$B$25=0,SQRT(Inputs!$B$8*F42/J42),(-Inputs!$B$25+SQRT(Inputs!$B$25^2+4*(1-Inputs!$B$25)*Inputs!$B$8*F42/J42))/(2*(1-Inputs!$B$25))),IF(B42="AD",Inputs!$B$8*F42/(2*J42),2*Inputs!$B$8*F42/J42)) -> 0.0041631936 | O42: =MIN(Inputs!$B$26,M42*L42) -> 0.0023504537 | P42: =MIN(Inputs!$B$26,O42*Inputs!$B$19) -> 0.023504537 | Q42: =MIN(O42,N42*Inputs!$B$21) -> 0.00020815968 | U42: =IF(COUNT(R42:T42)>0,"Published spec (+calc where blank)","Calculated (this workbook)") -> Calculated (this workbook) | V42: =IF(R42="",MAX(P42,W42),R42) -> 0.023504537 | W42: =IF(S42="",O42,S42) -> 0.0023504537 | X42: =IF(T42="",Q42,T42) -> 0.00020815968 | Y42: =IF(S42="","",IF(O42<S42,"Calc STRICTER (lower)","Calc more lenient (higher)")) | Z42: =IF(B42="XL","Hemizygous male AF (grpmax)","grpmax FAF95; check SAS, IndiGen, GenomeIndia") -> grpmax FAF95; check SAS, IndiGen, GenomeIndia
A43: CDH23 | B43: AR | C43: USH1 | D43: =SUMIF(Indian_Gene_Shares!$B$5:$B$47,A43,Indian_Gene_Shares!$G$5:$G$47) -> 0 | E43: =IFERROR(INDEX(ARIDE_Cohort!$C$6:$C$207,MATCH(A43,ARIDE_Cohort!$A$6:$A$207,0)),0) -> 0 | F43: =MAX(Inputs!$B$24,IF(AND(Inputs!$B$29="ARIDE cohort",ARIDE_Cohort!$B$3>=Inputs!$B$30),E43,D43)) -> 0.01 | G43: =IF(AND(Inputs!$B$29="ARIDE cohort",ARIDE_Cohort!$B$3>=Inputs!$B$30),IF(E43>Inputs!$B$24,"ARIDE cohort","Floor (ARIDE share below floor)"),IF(D43>Inputs!$B$24,"Indian literature",IF(D43>0,"Floor (Indian share below floor)","Floor (no Indian data)"))) -> Floor (no Indian data) | H43: =IF(B43="AR",Inputs!$B$14,IF(B43="AD",Inputs!$B$15,Inputs!$B$16)) -> 1 | J43: =IF(I43="",H43,I43) -> 1 | L43: =IF(K43="",Inputs!$B$20,K43) -> 0.5 | M43: =IF(B43="AR",SQRT(Inputs!$B$9*F43/J43),IF(B43="AD",Inputs!$B$9*F43/(2*J43),2*Inputs!$B$9*F43/J43)) -> 0.0047009074 | N43: =IF(B43="AR",IF(Inputs!$B$25=0,SQRT(Inputs!$B$8*F43/J43),(-Inputs!$B$25+SQRT(Inputs!$B$25^2+4*(1-Inputs!$B$25)*Inputs!$B$8*F43/J43))/(2*(1-Inputs!$B$25))),IF(B43="AD",Inputs!$B$8*F43/(2*J43),2*Inputs!$B$8*F43/J43)) -> 0.0041631936 | O43: =MIN(Inputs!$B$26,M43*L43) -> 0.0023504537 | P43: =MIN(Inputs!$B$26,O43*Inputs!$B$19) -> 0.023504537 | Q43: =MIN(O43,N43*Inputs!$B$21) -> 0.00020815968 | R43: 0.005 | S43: 0.003 | T43: 7e-05 | U43: =IF(COUNT(R43:T43)>0,"Published spec (+calc where blank)","Calculated (this workbook)") -> Published spec (+calc where blank) | V43: =IF(R43="",MAX(P43,W43),R43) -> 0.005 | W43: =IF(S43="",O43,S43) -> 0.003 | X43: =IF(T43="",Q43,T43) -> 7e-05 | Y43: =IF(S43="","",IF(O43<S43,"Calc STRICTER (lower)","Calc more lenient (higher)")) -> Calc STRICTER (lower) | Z43: =IF(B43="XL","Hemizygous male AF (grpmax)","grpmax FAF95; check SAS, IndiGen, GenomeIndia") -> grpmax FAF95; check SAS, IndiGen, GenomeIndia | AA43: ClinGen Hearing Loss VCEP v2 (AR): BA1 >=0.5%; BS1 >=0.3%; PM2_Sup <=0.007%
A44: CDH3 | B44: AR | C44: MD (HJMD) | D44: =SUMIF(Indian_Gene_Shares!$B$5:$B$47,A44,Indian_Gene_Shares!$G$5:$G$47) -> 0 | E44: =IFERROR(INDEX(ARIDE_Cohort!$C$6:$C$207,MATCH(A44,ARIDE_Cohort!$A$6:$A$207,0)),0) -> 0 | F44: =MAX(Inputs!$B$24,IF(AND(Inputs!$B$29="ARIDE cohort",ARIDE_Cohort!$B$3>=Inputs!$B$30),E44,D44)) -> 0.01 | G44: =IF(AND(Inputs!$B$29="ARIDE cohort",ARIDE_Cohort!$B$3>=Inputs!$B$30),IF(E44>Inputs!$B$24,"ARIDE cohort","Floor (ARIDE share below floor)"),IF(D44>Inputs!$B$24,"Indian literature",IF(D44>0,"Floor (Indian share below floor)","Floor (no Indian data)"))) -> Floor (no Indian data) | H44: =IF(B44="AR",Inputs!$B$14,IF(B44="AD",Inputs!$B$15,Inputs!$B$16)) -> 1 | J44: =IF(I44="",H44,I44) -> 1 | L44: =IF(K44="",Inputs!$B$20,K44) -> 0.5 | M44: =IF(B44="AR",SQRT(Inputs!$B$9*F44/J44),IF(B44="AD",Inputs!$B$9*F44/(2*J44),2*Inputs!$B$9*F44/J44)) -> 0.0047009074 | N44: =IF(B44="AR",IF(Inputs!$B$25=0,SQRT(Inputs!$B$8*F44/J44),(-Inputs!$B$25+SQRT(Inputs!$B$25^2+4*(1-Inputs!$B$25)*Inputs!$B$8*F44/J44))/(2*(1-Inputs!$B$25))),IF(B44="AD",Inputs!$B$8*F44/(2*J44),2*Inputs!$B$8*F44/J44)) -> 0.0041631936 | O44: =MIN(Inputs!$B$26,M44*L44) -> 0.0023504537 | P44: =MIN(Inputs!$B$26,O44*Inputs!$B$19) -> 0.023504537 | Q44: =MIN(O44,N44*Inputs!$B$21) -> 0.00020815968 | U44: =IF(COUNT(R44:T44)>0,"Published spec (+calc where blank)","Calculated (this workbook)") -> Calculated (this workbook) | V44: =IF(R44="",MAX(P44,W44),R44) -> 0.023504537 | W44: =IF(S44="",O44,S44) -> 0.0023504537 | X44: =IF(T44="",Q44,T44) -> 0.00020815968 | Y44: =IF(S44="","",IF(O44<S44,"Calc STRICTER (lower)","Calc more lenient (higher)")) | Z44: =IF(B44="XL","Hemizygous male AF (grpmax)","grpmax FAF95; check SAS, IndiGen, GenomeIndia") -> grpmax FAF95; check SAS, IndiGen, GenomeIndia
A45: CDHR1 | B45: AR | C45: CRD | D45: =SUMIF(Indian_Gene_Shares!$B$5:$B$47,A45,Indian_Gene_Shares!$G$5:$G$47) -> 0 | E45: =IFERROR(INDEX(ARIDE_Cohort!$C$6:$C$207,MATCH(A45,ARIDE_Cohort!$A$6:$A$207,0)),0) -> 0 | F45: =MAX(Inputs!$B$24,IF(AND(Inputs!$B$29="ARIDE cohort",ARIDE_Cohort!$B$3>=Inputs!$B$30),E45,D45)) -> 0.01 | G45: =IF(AND(Inputs!$B$29="ARIDE cohort",ARIDE_Cohort!$B$3>=Inputs!$B$30),IF(E45>Inputs!$B$24,"ARIDE cohort","Floor (ARIDE share below floor)"),IF(D45>Inputs!$B$24,"Indian literature",IF(D45>0,"Floor (Indian share below floor)","Floor (no Indian data)"))) -> Floor (no Indian data) | H45: =IF(B45="AR",Inputs!$B$14,IF(B45="AD",Inputs!$B$15,Inputs!$B$16)) -> 1 | J45: =IF(I45="",H45,I45) -> 1 | L45: =IF(K45="",Inputs!$B$20,K45) -> 0.5 | M45: =IF(B45="AR",SQRT(Inputs!$B$9*F45/J45),IF(B45="AD",Inputs!$B$9*F45/(2*J45),2*Inputs!$B$9*F45/J45)) -> 0.0047009074 | N45: =IF(B45="AR",IF(Inputs!$B$25=0,SQRT(Inputs!$B$8*F45/J45),(-Inputs!$B$25+SQRT(Inputs!$B$25^2+4*(1-Inputs!$B$25)*Inputs!$B$8*F45/J45))/(2*(1-Inputs!$B$25))),IF(B45="AD",Inputs!$B$8*F45/(2*J45),2*Inputs!$B$8*F45/J45)) -> 0.0041631936 | O45: =MIN(Inputs!$B$26,M45*L45) -> 0.0023504537 | P45: =MIN(Inputs!$B$26,O45*Inputs!$B$19) -> 0.023504537 | Q45: =MIN(O45,N45*Inputs!$B$21) -> 0.00020815968 | U45: =IF(COUNT(R45:T45)>0,"Published spec (+calc where blank)","Calculated (this workbook)") -> Calculated (this workbook) | V45: =IF(R45="",MAX(P45,W45),R45) -> 0.023504537 | W45: =IF(S45="",O45,S45) -> 0.0023504537 | X45: =IF(T45="",Q45,T45) -> 0.00020815968 | Y45: =IF(S45="","",IF(O45<S45,"Calc STRICTER (lower)","Calc more lenient (higher)")) | Z45: =IF(B45="XL","Hemizygous male AF (grpmax)","grpmax FAF95; check SAS, IndiGen, GenomeIndia") -> grpmax FAF95; check SAS, IndiGen, GenomeIndia
A46: CEP164 | B46: AR | C46: SLS/RP | D46: =SUMIF(Indian_Gene_Shares!$B$5:$B$47,A46,Indian_Gene_Shares!$G$5:$G$47) -> 0 | E46: =IFERROR(INDEX(ARIDE_Cohort!$C$6:$C$207,MATCH(A46,ARIDE_Cohort!$A$6:$A$207,0)),0) -> 0 | F46: =MAX(Inputs!$B$24,IF(AND(Inputs!$B$29="ARIDE cohort",ARIDE_Cohort!$B$3>=Inputs!$B$30),E46,D46)) -> 0.01 | G46: =IF(AND(Inputs!$B$29="ARIDE cohort",ARIDE_Cohort!$B$3>=Inputs!$B$30),IF(E46>Inputs!$B$24,"ARIDE cohort","Floor (ARIDE share below floor)"),IF(D46>Inputs!$B$24,"Indian literature",IF(D46>0,"Floor (Indian share below floor)","Floor (no Indian data)"))) -> Floor (no Indian data) | H46: =IF(B46="AR",Inputs!$B$14,IF(B46="AD",Inputs!$B$15,Inputs!$B$16)) -> 1 | J46: =IF(I46="",H46,I46) -> 1 | L46: =IF(K46="",Inputs!$B$20,K46) -> 0.5 | M46: =IF(B46="AR",SQRT(Inputs!$B$9*F46/J46),IF(B46="AD",Inputs!$B$9*F46/(2*J46),2*Inputs!$B$9*F46/J46)) -> 0.0047009074 | N46: =IF(B46="AR",IF(Inputs!$B$25=0,SQRT(Inputs!$B$8*F46/J46),(-Inputs!$B$25+SQRT(Inputs!$B$25^2+4*(1-Inputs!$B$25)*Inputs!$B$8*F46/J46))/(2*(1-Inputs!$B$25))),IF(B46="AD",Inputs!$B$8*F46/(2*J46),2*Inputs!$B$8*F46/J46)) -> 0.0041631936 | O46: =MIN(Inputs!$B$26,M46*L46) -> 0.0023504537 | P46: =MIN(Inputs!$B$26,O46*Inputs!$B$19) -> 0.023504537 | Q46: =MIN(O46,N46*Inputs!$B$21) -> 0.00020815968 | U46: =IF(COUNT(R46:T46)>0,"Published spec (+calc where blank)","Calculated (this workbook)") -> Calculated (this workbook) | V46: =IF(R46="",MAX(P46,W46),R46) -> 0.023504537 | W46: =IF(S46="",O46,S46) -> 0.0023504537 | X46: =IF(T46="",Q46,T46) -> 0.00020815968 | Y46: =IF(S46="","",IF(O46<S46,"Calc STRICTER (lower)","Calc more lenient (higher)")) | Z46: =IF(B46="XL","Hemizygous male AF (grpmax)","grpmax FAF95; check SAS, IndiGen, GenomeIndia") -> grpmax FAF95; check SAS, IndiGen, GenomeIndia
A47: CEP250 | B47: AR | C47: USH-atypical | D47: =SUMIF(Indian_Gene_Shares!$B$5:$B$47,A47,Indian_Gene_Shares!$G$5:$G$47) -> 0 | E47: =IFERROR(INDEX(ARIDE_Cohort!$C$6:$C$207,MATCH(A47,ARIDE_Cohort!$A$6:$A$207,0)),0) -> 0 | F47: =MAX(Inputs!$B$24,IF(AND(Inputs!$B$29="ARIDE cohort",ARIDE_Cohort!$B$3>=Inputs!$B$30),E47,D47)) -> 0.01 | G47: =IF(AND(Inputs!$B$29="ARIDE cohort",ARIDE_Cohort!$B$3>=Inputs!$B$30),IF(E47>Inputs!$B$24,"ARIDE cohort","Floor (ARIDE share below floor)"),IF(D47>Inputs!$B$24,"Indian literature",IF(D47>0,"Floor (Indian share below floor)","Floor (no Indian data)"))) -> Floor (no Indian data) | H47: =IF(B47="AR",Inputs!$B$14,IF(B47="AD",Inputs!$B$15,Inputs!$B$16)) -> 1 | J47: =IF(I47="",H47,I47) -> 1 | L47: =IF(K47="",Inputs!$B$20,K47) -> 0.5 | M47: =IF(B47="AR",SQRT(Inputs!$B$9*F47/J47),IF(B47="AD",Inputs!$B$9*F47/(2*J47),2*Inputs!$B$9*F47/J47)) -> 0.0047009074 | N47: =IF(B47="AR",IF(Inputs!$B$25=0,SQRT(Inputs!$B$8*F47/J47),(-Inputs!$B$25+SQRT(Inputs!$B$25^2+4*(1-Inputs!$B$25)*Inputs!$B$8*F47/J47))/(2*(1-Inputs!$B$25))),IF(B47="AD",Inputs!$B$8*F47/(2*J47),2*Inputs!$B$8*F47/J47)) -> 0.0041631936 | O47: =MIN(Inputs!$B$26,M47*L47) -> 0.0023504537 | P47: =MIN(Inputs!$B$26,O47*Inputs!$B$19) -> 0.023504537 | Q47: =MIN(O47,N47*Inputs!$B$21) -> 0.00020815968 | U47: =IF(COUNT(R47:T47)>0,"Published spec (+calc where blank)","Calculated (this workbook)") -> Calculated (this workbook) | V47: =IF(R47="",MAX(P47,W47),R47) -> 0.023504537 | W47: =IF(S47="",O47,S47) -> 0.0023504537 | X47: =IF(T47="",Q47,T47) -> 0.00020815968 | Y47: =IF(S47="","",IF(O47<S47,"Calc STRICTER (lower)","Calc more lenient (higher)")) | Z47: =IF(B47="XL","Hemizygous male AF (grpmax)","grpmax FAF95; check SAS, IndiGen, GenomeIndia") -> grpmax FAF95; check SAS, IndiGen, GenomeIndia
A48: CEP290 | B48: AR | C48: LCA/JS/SLS | D48: =SUMIF(Indian_Gene_Shares!$B$5:$B$47,A48,Indian_Gene_Shares!$G$5:$G$47) -> 0.001915511 | E48: =IFERROR(INDEX(ARIDE_Cohort!$C$6:$C$207,MATCH(A48,ARIDE_Cohort!$A$6:$A$207,0)),0) -> 0 | F48: =MAX(Inputs!$B$24,IF(AND(Inputs!$B$29="ARIDE cohort",ARIDE_Cohort!$B$3>=Inputs!$B$30),E48,D48)) -> 0.01 | G48: =IF(AND(Inputs!$B$29="ARIDE cohort",ARIDE_Cohort!$B$3>=Inputs!$B$30),IF(E48>Inputs!$B$24,"ARIDE cohort","Floor (ARIDE share below floor)"),IF(D48>Inputs!$B$24,"Indian literature",IF(D48>0,"Floor (Indian share below floor)","Floor (no Indian data)"))) -> Floor (Indian share below floor) | H48: =IF(B48="AR",Inputs!$B$14,IF(B48="AD",Inputs!$B$15,Inputs!$B$16)) -> 1 | J48: =IF(I48="",H48,I48) -> 1 | L48: =IF(K48="",Inputs!$B$20,K48) -> 0.5 | M48: =IF(B48="AR",SQRT(Inputs!$B$9*F48/J48),IF(B48="AD",Inputs!$B$9*F48/(2*J48),2*Inputs!$B$9*F48/J48)) -> 0.0047009074 | N48: =IF(B48="AR",IF(Inputs!$B$25=0,SQRT(Inputs!$B$8*F48/J48),(-Inputs!$B$25+SQRT(Inputs!$B$25^2+4*(1-Inputs!$B$25)*Inputs!$B$8*F48/J48))/(2*(1-Inputs!$B$25))),IF(B48="AD",Inputs!$B$8*F48/(2*J48),2*Inputs!$B$8*F48/J48)) -> 0.0041631936 | O48: =MIN(Inputs!$B$26,M48*L48) -> 0.0023504537 | P48: =MIN(Inputs!$B$26,O48*Inputs!$B$19) -> 0.023504537 | Q48: =MIN(O48,N48*Inputs!$B$21) -> 0.00020815968 | U48: =IF(COUNT(R48:T48)>0,"Published spec (+calc where blank)","Calculated (this workbook)") -> Calculated (this workbook) | V48: =IF(R48="",MAX(P48,W48),R48) -> 0.023504537 | W48: =IF(S48="",O48,S48) -> 0.0023504537 | X48: =IF(T48="",Q48,T48) -> 0.00020815968 | Y48: =IF(S48="","",IF(O48<S48,"Calc STRICTER (lower)","Calc more lenient (higher)")) | Z48: =IF(B48="XL","Hemizygous male AF (grpmax)","grpmax FAF95; check SAS, IndiGen, GenomeIndia") -> grpmax FAF95; check SAS, IndiGen, GenomeIndia
A49: CEP78 | B49: AR | C49: CRD+HL | D49: =SUMIF(Indian_Gene_Shares!$B$5:$B$47,A49,Indian_Gene_Shares!$G$5:$G$47) -> 0 | E49: =IFERROR(INDEX(ARIDE_Cohort!$C$6:$C$207,MATCH(A49,ARIDE_Cohort!$A$6:$A$207,0)),0) -> 0 | F49: =MAX(Inputs!$B$24,IF(AND(Inputs!$B$29="ARIDE cohort",ARIDE_Cohort!$B$3>=Inputs!$B$30),E49,D49)) -> 0.01 | G49: =IF(AND(Inputs!$B$29="ARIDE cohort",ARIDE_Cohort!$B$3>=Inputs!$B$30),IF(E49>Inputs!$B$24,"ARIDE cohort","Floor (ARIDE share below floor)"),IF(D49>Inputs!$B$24,"Indian literature",IF(D49>0,"Floor (Indian share below floor)","Floor (no Indian data)"))) -> Floor (no Indian data) | H49: =IF(B49="AR",Inputs!$B$14,IF(B49="AD",Inputs!$B$15,Inputs!$B$16)) -> 1 | J49: =IF(I49="",H49,I49) -> 1 | L49: =IF(K49="",Inputs!$B$20,K49) -> 0.5 | M49: =IF(B49="AR",SQRT(Inputs!$B$9*F49/J49),IF(B49="AD",Inputs!$B$9*F49/(2*J49),2*Inputs!$B$9*F49/J49)) -> 0.0047009074 | N49: =IF(B49="AR",IF(Inputs!$B$25=0,SQRT(Inputs!$B$8*F49/J49),(-Inputs!$B$25+SQRT(Inputs!$B$25^2+4*(1-Inputs!$B$25)*Inputs!$B$8*F49/J49))/(2*(1-Inputs!$B$25))),IF(B49="AD",Inputs!$B$8*F49/(2*J49),2*Inputs!$B$8*F49/J49)) -> 0.0041631936 | O49: =MIN(Inputs!$B$26,M49*L49) -> 0.0023504537 | P49: =MIN(Inputs!$B$26,O49*Inputs!$B$19) -> 0.023504537 | Q49: =MIN(O49,N49*Inputs!$B$21) -> 0.00020815968 | U49: =IF(COUNT(R49:T49)>0,"Published spec (+calc where blank)","Calculated (this workbook)") -> Calculated (this workbook) | V49: =IF(R49="",MAX(P49,W49),R49) -> 0.023504537 | W49: =IF(S49="",O49,S49) -> 0.0023504537 | X49: =IF(T49="",Q49,T49) -> 0.00020815968 | Y49: =IF(S49="","",IF(O49<S49,"Calc STRICTER (lower)","Calc more lenient (higher)")) | Z49: =IF(B49="XL","Hemizygous male AF (grpmax)","grpmax FAF95; check SAS, IndiGen, GenomeIndia") -> grpmax FAF95; check SAS, IndiGen, GenomeIndia
A50: CERKL | B50: AR | C50: RP/CRD | D50: =SUMIF(Indian_Gene_Shares!$B$5:$B$47,A50,Indian_Gene_Shares!$G$5:$G$47) -> 0.11719997 | E50: =IFERROR(INDEX(ARIDE_Cohort!$C$6:$C$207,MATCH(A50,ARIDE_Cohort!$A$6:$A$207,0)),0) -> 0 | F50: =MAX(Inputs!$B$24,IF(AND(Inputs!$B$29="ARIDE cohort",ARIDE_Cohort!$B$3>=Inputs!$B$30),E50,D50)) -> 0.11719997 | G50: =IF(AND(Inputs!$B$29="ARIDE cohort",ARIDE_Cohort!$B$3>=Inputs!$B$30),IF(E50>Inputs!$B$24,"ARIDE cohort","Floor (ARIDE share below floor)"),IF(D50>Inputs!$B$24,"Indian literature",IF(D50>0,"Floor (Indian share below floor)","Floor (no Indian data)"))) -> Indian literature | H50: =IF(B50="AR",Inputs!$B$14,IF(B50="AD",Inputs!$B$15,Inputs!$B$16)) -> 1 | J50: =IF(I50="",H50,I50) -> 1 | K50: 0.85 | L50: =IF(K50="",Inputs!$B$20,K50) -> 0.85 | M50: =IF(B50="AR",SQRT(Inputs!$B$9*F50/J50),IF(B50="AD",Inputs!$B$9*F50/(2*J50),2*Inputs!$B$9*F50/J50)) -> 0.016093312 | N50: =IF(B50="AR",IF(Inputs!$B$25=0,SQRT(Inputs!$B$8*F50/J50),(-Inputs!$B$25+SQRT(Inputs!$B$25^2+4*(1-Inputs!$B$25)*Inputs!$B$8*F50/J50))/(2*(1-Inputs!$B$25))),IF(B50="AD",Inputs!$B$8*F50/(2*J50),2*Inputs!$B$8*F50/J50)) -> 0.014252477 | O50: =MIN(Inputs!$B$26,M50*L50) -> 0.013679316 | P50: =MIN(Inputs!$B$26,O50*Inputs!$B$19) -> 0.05 | Q50: =MIN(O50,N50*Inputs!$B$21) -> 0.00071262385 | U50: =IF(COUNT(R50:T50)>0,"Published spec (+calc where blank)","Calculated (this workbook)") -> Calculated (this workbook) | V50: =IF(R50="",MAX(P50,W50),R50) -> 0.05 | W50: =IF(S50="",O50,S50) -> 0.013679316 | X50: =IF(T50="",Q50,T50) -> 0.00071262385 | Y50: =IF(S50="","",IF(O50<S50,"Calc STRICTER (lower)","Calc more lenient (higher)")) | Z50: =IF(B50="XL","Hemizygous male AF (grpmax)","grpmax FAF95; check SAS, IndiGen, GenomeIndia") -> grpmax FAF95; check SAS, IndiGen, GenomeIndia | AB50: Indian founder allele: 12 of 14 CERKL-positive unrelated RP patients shared one mutation (Sen et al. 2020, cited in Front Genet 2022;13:858556)
A51: CFAP410 | B51: AR | C51: RP/CRD | D51: =SUMIF(Indian_Gene_Shares!$B$5:$B$47,A51,Indian_Gene_Shares!$G$5:$G$47) -> 0 | E51: =IFERROR(INDEX(ARIDE_Cohort!$C$6:$C$207,MATCH(A51,ARIDE_Cohort!$A$6:$A$207,0)),0) -> 0 | F51: =MAX(Inputs!$B$24,IF(AND(Inputs!$B$29="ARIDE cohort",ARIDE_Cohort!$B$3>=Inputs!$B$30),E51,D51)) -> 0.01 | G51: =IF(AND(Inputs!$B$29="ARIDE cohort",ARIDE_Cohort!$B$3>=Inputs!$B$30),IF(E51>Inputs!$B$24,"ARIDE cohort","Floor (ARIDE share below floor)"),IF(D51>Inputs!$B$24,"Indian literature",IF(D51>0,"Floor (Indian share below floor)","Floor (no Indian data)"))) -> Floor (no Indian data) | H51: =IF(B51="AR",Inputs!$B$14,IF(B51="AD",Inputs!$B$15,Inputs!$B$16)) -> 1 | J51: =IF(I51="",H51,I51) -> 1 | L51: =IF(K51="",Inputs!$B$20,K51) -> 0.5 | M51: =IF(B51="AR",SQRT(Inputs!$B$9*F51/J51),IF(B51="AD",Inputs!$B$9*F51/(2*J51),2*Inputs!$B$9*F51/J51)) -> 0.0047009074 | N51: =IF(B51="AR",IF(Inputs!$B$25=0,SQRT(Inputs!$B$8*F51/J51),(-Inputs!$B$25+SQRT(Inputs!$B$25^2+4*(1-Inputs!$B$25)*Inputs!$B$8*F51/J51))/(2*(1-Inputs!$B$25))),IF(B51="AD",Inputs!$B$8*F51/(2*J51),2*Inputs!$B$8*F51/J51)) -> 0.0041631936 | O51: =MIN(Inputs!$B$26,M51*L51) -> 0.0023504537 | P51: =MIN(Inputs!$B$26,O51*Inputs!$B$19) -> 0.023504537 | Q51: =MIN(O51,N51*Inputs!$B$21) -> 0.00020815968 | U51: =IF(COUNT(R51:T51)>0,"Published spec (+calc where blank)","Calculated (this workbook)") -> Calculated (this workbook) | V51: =IF(R51="",MAX(P51,W51),R51) -> 0.023504537 | W51: =IF(S51="",O51,S51) -> 0.0023504537 | X51: =IF(T51="",Q51,T51) -> 0.00020815968 | Y51: =IF(S51="","",IF(O51<S51,"Calc STRICTER (lower)","Calc more lenient (higher)")) | Z51: =IF(B51="XL","Hemizygous male AF (grpmax)","grpmax FAF95; check SAS, IndiGen, GenomeIndia") -> grpmax FAF95; check SAS, IndiGen, GenomeIndia
A52: CHM | B52: XL | C52: Choroideremia | D52: =SUMIF(Indian_Gene_Shares!$B$5:$B$47,A52,Indian_Gene_Shares!$G$5:$G$47) -> 0 | E52: =IFERROR(INDEX(ARIDE_Cohort!$C$6:$C$207,MATCH(A52,ARIDE_Cohort!$A$6:$A$207,0)),0) -> 0 | F52: =MAX(Inputs!$B$24,IF(AND(Inputs!$B$29="ARIDE cohort",ARIDE_Cohort!$B$3>=Inputs!$B$30),E52,D52)) -> 0.01 | G52: =IF(AND(Inputs!$B$29="ARIDE cohort",ARIDE_Cohort!$B$3>=Inputs!$B$30),IF(E52>Inputs!$B$24,"ARIDE cohort","Floor (ARIDE share below floor)"),IF(D52>Inputs!$B$24,"Indian literature",IF(D52>0,"Floor (Indian share below floor)","Floor (no Indian data)"))) -> Floor (no Indian data) | H52: =IF(B52="AR",Inputs!$B$14,IF(B52="AD",Inputs!$B$15,Inputs!$B$16)) -> 1 | J52: =IF(I52="",H52,I52) -> 1 | L52: =IF(K52="",Inputs!$B$20,K52) -> 0.5 | M52: =IF(B52="AR",SQRT(Inputs!$B$9*F52/J52),IF(B52="AD",Inputs!$B$9*F52/(2*J52),2*Inputs!$B$9*F52/J52)) -> 4.4197061e-05 | N52: =IF(B52="AR",IF(Inputs!$B$25=0,SQRT(Inputs!$B$8*F52/J52),(-Inputs!$B$25+SQRT(Inputs!$B$25^2+4*(1-Inputs!$B$25)*Inputs!$B$8*F52/J52))/(2*(1-Inputs!$B$25))),IF(B52="AD",Inputs!$B$8*F52/(2*J52),2*Inputs!$B$8*F52/J52)) -> 3.4664362e-05 | O52: =MIN(Inputs!$B$26,M52*L52) -> 2.2098531e-05 | P52: =MIN(Inputs!$B$26,O52*Inputs!$B$19) -> 0.00022098531 | Q52: =MIN(O52,N52*Inputs!$B$21) -> 1.7332181e-06 | U52: =IF(COUNT(R52:T52)>0,"Published spec (+calc where blank)","Calculated (this workbook)") -> Calculated (this workbook) | V52: =IF(R52="",MAX(P52,W52),R52) -> 0.00022098531 | W52: =IF(S52="",O52,S52) -> 2.2098531e-05 | X52: =IF(T52="",Q52,T52) -> 1.7332181e-06 | Y52: =IF(S52="","",IF(O52<S52,"Calc STRICTER (lower)","Calc more lenient (higher)")) | Z52: =IF(B52="XL","Hemizygous male AF (grpmax)","grpmax FAF95; check SAS, IndiGen, GenomeIndia") -> Hemizygous male AF (grpmax)
A53: CLCC1 | B53: AR | C53: RP | D53: =SUMIF(Indian_Gene_Shares!$B$5:$B$47,A53,Indian_Gene_Shares!$G$5:$G$47) -> 0 | E53: =IFERROR(INDEX(ARIDE_Cohort!$C$6:$C$207,MATCH(A53,ARIDE_Cohort!$A$6:$A$207,0)),0) -> 0 | F53: =MAX(Inputs!$B$24,IF(AND(Inputs!$B$29="ARIDE cohort",ARIDE_Cohort!$B$3>=Inputs!$B$30),E53,D53)) -> 0.01 | G53: =IF(AND(Inputs!$B$29="ARIDE cohort",ARIDE_Cohort!$B$3>=Inputs!$B$30),IF(E53>Inputs!$B$24,"ARIDE cohort","Floor (ARIDE share below floor)"),IF(D53>Inputs!$B$24,"Indian literature",IF(D53>0,"Floor (Indian share below floor)","Floor (no Indian data)"))) -> Floor (no Indian data) | H53: =IF(B53="AR",Inputs!$B$14,IF(B53="AD",Inputs!$B$15,Inputs!$B$16)) -> 1 | J53: =IF(I53="",H53,I53) -> 1 | L53: =IF(K53="",Inputs!$B$20,K53) -> 0.5 | M53: =IF(B53="AR",SQRT(Inputs!$B$9*F53/J53),IF(B53="AD",Inputs!$B$9*F53/(2*J53),2*Inputs!$B$9*F53/J53)) -> 0.0047009074 | N53: =IF(B53="AR",IF(Inputs!$B$25=0,SQRT(Inputs!$B$8*F53/J53),(-Inputs!$B$25+SQRT(Inputs!$B$25^2+4*(1-Inputs!$B$25)*Inputs!$B$8*F53/J53))/(2*(1-Inputs!$B$25))),IF(B53="AD",Inputs!$B$8*F53/(2*J53),2*Inputs!$B$8*F53/J53)) -> 0.0041631936 | O53: =MIN(Inputs!$B$26,M53*L53) -> 0.0023504537 | P53: =MIN(Inputs!$B$26,O53*Inputs!$B$19) -> 0.023504537 | Q53: =MIN(O53,N53*Inputs!$B$21) -> 0.00020815968 | U53: =IF(COUNT(R53:T53)>0,"Published spec (+calc where blank)","Calculated (this workbook)") -> Calculated (this workbook) | V53: =IF(R53="",MAX(P53,W53),R53) -> 0.023504537 | W53: =IF(S53="",O53,S53) -> 0.0023504537 | X53: =IF(T53="",Q53,T53) -> 0.00020815968 | Y53: =IF(S53="","",IF(O53<S53,"Calc STRICTER (lower)","Calc more lenient (higher)")) | Z53: =IF(B53="XL","Hemizygous male AF (grpmax)","grpmax FAF95; check SAS, IndiGen, GenomeIndia") -> grpmax FAF95; check SAS, IndiGen, GenomeIndia
A54: CLN3 | B54: AR | C54: NCL/RP | D54: =SUMIF(Indian_Gene_Shares!$B$5:$B$47,A54,Indian_Gene_Shares!$G$5:$G$47) -> 0 | E54: =IFERROR(INDEX(ARIDE_Cohort!$C$6:$C$207,MATCH(A54,ARIDE_Cohort!$A$6:$A$207,0)),0) -> 0 | F54: =MAX(Inputs!$B$24,IF(AND(Inputs!$B$29="ARIDE cohort",ARIDE_Cohort!$B$3>=Inputs!$B$30),E54,D54)) -> 0.01 | G54: =IF(AND(Inputs!$B$29="ARIDE cohort",ARIDE_Cohort!$B$3>=Inputs!$B$30),IF(E54>Inputs!$B$24,"ARIDE cohort","Floor (ARIDE share below floor)"),IF(D54>Inputs!$B$24,"Indian literature",IF(D54>0,"Floor (Indian share below floor)","Floor (no Indian data)"))) -> Floor (no Indian data) | H54: =IF(B54="AR",Inputs!$B$14,IF(B54="AD",Inputs!$B$15,Inputs!$B$16)) -> 1 | J54: =IF(I54="",H54,I54) -> 1 | L54: =IF(K54="",Inputs!$B$20,K54) -> 0.5 | M54: =IF(B54="AR",SQRT(Inputs!$B$9*F54/J54),IF(B54="AD",Inputs!$B$9*F54/(2*J54),2*Inputs!$B$9*F54/J54)) -> 0.0047009074 | N54: =IF(B54="AR",IF(Inputs!$B$25=0,SQRT(Inputs!$B$8*F54/J54),(-Inputs!$B$25+SQRT(Inputs!$B$25^2+4*(1-Inputs!$B$25)*Inputs!$B$8*F54/J54))/(2*(1-Inputs!$B$25))),IF(B54="AD",Inputs!$B$8*F54/(2*J54),2*Inputs!$B$8*F54/J54)) -> 0.0041631936 | O54: =MIN(Inputs!$B$26,M54*L54) -> 0.0023504537 | P54: =MIN(Inputs!$B$26,O54*Inputs!$B$19) -> 0.023504537 | Q54: =MIN(O54,N54*Inputs!$B$21) -> 0.00020815968 | U54: =IF(COUNT(R54:T54)>0,"Published spec (+calc where blank)","Calculated (this workbook)") -> Calculated (this workbook) | V54: =IF(R54="",MAX(P54,W54),R54) -> 0.023504537 | W54: =IF(S54="",O54,S54) -> 0.0023504537 | X54: =IF(T54="",Q54,T54) -> 0.00020815968 | Y54: =IF(S54="","",IF(O54<S54,"Calc STRICTER (lower)","Calc more lenient (higher)")) | Z54: =IF(B54="XL","Hemizygous male AF (grpmax)","grpmax FAF95; check SAS, IndiGen, GenomeIndia") -> grpmax FAF95; check SAS, IndiGen, GenomeIndia
A55: CLN5 | B55: AR | C55: NCL | D55: =SUMIF(Indian_Gene_Shares!$B$5:$B$47,A55,Indian_Gene_Shares!$G$5:$G$47) -> 0 | E55: =IFERROR(INDEX(ARIDE_Cohort!$C$6:$C$207,MATCH(A55,ARIDE_Cohort!$A$6:$A$207,0)),0) -> 0 | F55: =MAX(Inputs!$B$24,IF(AND(Inputs!$B$29="ARIDE cohort",ARIDE_Cohort!$B$3>=Inputs!$B$30),E55,D55)) -> 0.01 | G55: =IF(AND(Inputs!$B$29="ARIDE cohort",ARIDE_Cohort!$B$3>=Inputs!$B$30),IF(E55>Inputs!$B$24,"ARIDE cohort","Floor (ARIDE share below floor)"),IF(D55>Inputs!$B$24,"Indian literature",IF(D55>0,"Floor (Indian share below floor)","Floor (no Indian data)"))) -> Floor (no Indian data) | H55: =IF(B55="AR",Inputs!$B$14,IF(B55="AD",Inputs!$B$15,Inputs!$B$16)) -> 1 | J55: =IF(I55="",H55,I55) -> 1 | L55: =IF(K55="",Inputs!$B$20,K55) -> 0.5 | M55: =IF(B55="AR",SQRT(Inputs!$B$9*F55/J55),IF(B55="AD",Inputs!$B$9*F55/(2*J55),2*Inputs!$B$9*F55/J55)) -> 0.0047009074 | N55: =IF(B55="AR",IF(Inputs!$B$25=0,SQRT(Inputs!$B$8*F55/J55),(-Inputs!$B$25+SQRT(Inputs!$B$25^2+4*(1-Inputs!$B$25)*Inputs!$B$8*F55/J55))/(2*(1-Inputs!$B$25))),IF(B55="AD",Inputs!$B$8*F55/(2*J55),2*Inputs!$B$8*F55/J55)) -> 0.0041631936 | O55: =MIN(Inputs!$B$26,M55*L55) -> 0.0023504537 | P55: =MIN(Inputs!$B$26,O55*Inputs!$B$19) -> 0.023504537 | Q55: =MIN(O55,N55*Inputs!$B$21) -> 0.00020815968 | U55: =IF(COUNT(R55:T55)>0,"Published spec (+calc where blank)","Calculated (this workbook)") -> Calculated (this workbook) | V55: =IF(R55="",MAX(P55,W55),R55) -> 0.023504537 | W55: =IF(S55="",O55,S55) -> 0.0023504537 | X55: =IF(T55="",Q55,T55) -> 0.00020815968 | Y55: =IF(S55="","",IF(O55<S55,"Calc STRICTER (lower)","Calc more lenient (higher)")) | Z55: =IF(B55="XL","Hemizygous male AF (grpmax)","grpmax FAF95; check SAS, IndiGen, GenomeIndia") -> grpmax FAF95; check SAS, IndiGen, GenomeIndia
A56: CLRN1 | B56: AR | C56: USH3/RP | D56: =SUMIF(Indian_Gene_Shares!$B$5:$B$47,A56,Indian_Gene_Shares!$G$5:$G$47) -> 0 | E56: =IFERROR(INDEX(ARIDE_Cohort!$C$6:$C$207,MATCH(A56,ARIDE_Cohort!$A$6:$A$207,0)),0) -> 0 | F56: =MAX(Inputs!$B$24,IF(AND(Inputs!$B$29="ARIDE cohort",ARIDE_Cohort!$B$3>=Inputs!$B$30),E56,D56)) -> 0.01 | G56: =IF(AND(Inputs!$B$29="ARIDE cohort",ARIDE_Cohort!$B$3>=Inputs!$B$30),IF(E56>Inputs!$B$24,"ARIDE cohort","Floor (ARIDE share below floor)"),IF(D56>Inputs!$B$24,"Indian literature",IF(D56>0,"Floor (Indian share below floor)","Floor (no Indian data)"))) -> Floor (no Indian data) | H56: =IF(B56="AR",Inputs!$B$14,IF(B56="AD",Inputs!$B$15,Inputs!$B$16)) -> 1 | J56: =IF(I56="",H56,I56) -> 1 | L56: =IF(K56="",Inputs!$B$20,K56) -> 0.5 | M56: =IF(B56="AR",SQRT(Inputs!$B$9*F56/J56),IF(B56="AD",Inputs!$B$9*F56/(2*J56),2*Inputs!$B$9*F56/J56)) -> 0.0047009074 | N56: =IF(B56="AR",IF(Inputs!$B$25=0,SQRT(Inputs!$B$8*F56/J56),(-Inputs!$B$25+SQRT(Inputs!$B$25^2+4*(1-Inputs!$B$25)*Inputs!$B$8*F56/J56))/(2*(1-Inputs!$B$25))),IF(B56="AD",Inputs!$B$8*F56/(2*J56),2*Inputs!$B$8*F56/J56)) -> 0.0041631936 | O56: =MIN(Inputs!$B$26,M56*L56) -> 0.0023504537 | P56: =MIN(Inputs!$B$26,O56*Inputs!$B$19) -> 0.023504537 | Q56: =MIN(O56,N56*Inputs!$B$21) -> 0.00020815968 | U56: =IF(COUNT(R56:T56)>0,"Published spec (+calc where blank)","Calculated (this workbook)") -> Calculated (this workbook) | V56: =IF(R56="",MAX(P56,W56),R56) -> 0.023504537 | W56: =IF(S56="",O56,S56) -> 0.0023504537 | X56: =IF(T56="",Q56,T56) -> 0.00020815968 | Y56: =IF(S56="","",IF(O56<S56,"Calc STRICTER (lower)","Calc more lenient (higher)")) | Z56: =IF(B56="XL","Hemizygous male AF (grpmax)","grpmax FAF95; check SAS, IndiGen, GenomeIndia") -> grpmax FAF95; check SAS, IndiGen, GenomeIndia
A57: CNGA1 | B57: AR | C57: RP | D57: =SUMIF(Indian_Gene_Shares!$B$5:$B$47,A57,Indian_Gene_Shares!$G$5:$G$47) -> 0.023078457 | E57: =IFERROR(INDEX(ARIDE_Cohort!$C$6:$C$207,MATCH(A57,ARIDE_Cohort!$A$6:$A$207,0)),0) -> 0 | F57: =MAX(Inputs!$B$24,IF(AND(Inputs!$B$29="ARIDE cohort",ARIDE_Cohort!$B$3>=Inputs!$B$30),E57,D57)) -> 0.023078457 | G57: =IF(AND(Inputs!$B$29="ARIDE cohort",ARIDE_Cohort!$B$3>=Inputs!$B$30),IF(E57>Inputs!$B$24,"ARIDE cohort","Floor (ARIDE share below floor)"),IF(D57>Inputs!$B$24,"Indian literature",IF(D57>0,"Floor (Indian share below floor)","Floor (no Indian data)"))) -> Indian literature | H57: =IF(B57="AR",Inputs!$B$14,IF(B57="AD",Inputs!$B$15,Inputs!$B$16)) -> 1 | J57: =IF(I57="",H57,I57) -> 1 | L57: =IF(K57="",Inputs!$B$20,K57) -> 0.5 | M57: =IF(B57="AR",SQRT(Inputs!$B$9*F57/J57),IF(B57="AD",Inputs!$B$9*F57/(2*J57),2*Inputs!$B$9*F57/J57)) -> 0.0071414284 | N57: =IF(B57="AR",IF(Inputs!$B$25=0,SQRT(Inputs!$B$8*F57/J57),(-Inputs!$B$25+SQRT(Inputs!$B$25^2+4*(1-Inputs!$B$25)*Inputs!$B$8*F57/J57))/(2*(1-Inputs!$B$25))),IF(B57="AD",Inputs!$B$8*F57/(2*J57),2*Inputs!$B$8*F57/J57)) -> 0.0063245553 | O57: =MIN(Inputs!$B$26,M57*L57) -> 0.0035707142 | P57: =MIN(Inputs!$B$26,O57*Inputs!$B$19) -> 0.035707142 | Q57: =MIN(O57,N57*Inputs!$B$21) -> 0.00031622777 | U57: =IF(COUNT(R57:T57)>0,"Published spec (+calc where blank)","Calculated (this workbook)") -> Calculated (this workbook) | V57: =IF(R57="",MAX(P57,W57),R57) -> 0.035707142 | W57: =IF(S57="",O57,S57) -> 0.0035707142 | X57: =IF(T57="",Q57,T57) -> 0.00031622777 | Y57: =IF(S57="","",IF(O57<S57,"Calc STRICTER (lower)","Calc more lenient (higher)")) | Z57: =IF(B57="XL","Hemizygous male AF (grpmax)","grpmax FAF95; check SAS, IndiGen, GenomeIndia") -> grpmax FAF95; check SAS, IndiGen, GenomeIndia
A58: CNGA3 | B58: AR | C58: ACHM | D58: =SUMIF(Indian_Gene_Shares!$B$5:$B$47,A58,Indian_Gene_Shares!$G$5:$G$47) -> 0.0059267097 | E58: =IFERROR(INDEX(ARIDE_Cohort!$C$6:$C$207,MATCH(A58,ARIDE_Cohort!$A$6:$A$207,0)),0) -> 0 | F58: =MAX(Inputs!$B$24,IF(AND(Inputs!$B$29="ARIDE cohort",ARIDE_Cohort!$B$3>=Inputs!$B$30),E58,D58)) -> 0.01 | G58: =IF(AND(Inputs!$B$29="ARIDE cohort",ARIDE_Cohort!$B$3>=Inputs!$B$30),IF(E58>Inputs!$B$24,"ARIDE cohort","Floor (ARIDE share below floor)"),IF(D58>Inputs!$B$24,"Indian literature",IF(D58>0,"Floor (Indian share below floor)","Floor (no Indian data)"))) -> Floor (Indian share below floor) | H58: =IF(B58="AR",Inputs!$B$14,IF(B58="AD",Inputs!$B$15,Inputs!$B$16)) -> 1 | J58: =IF(I58="",H58,I58) -> 1 | L58: =IF(K58="",Inputs!$B$20,K58) -> 0.5 | M58: =IF(B58="AR",SQRT(Inputs!$B$9*F58/J58),IF(B58="AD",Inputs!$B$9*F58/(2*J58),2*Inputs!$B$9*F58/J58)) -> 0.0047009074 | N58: =IF(B58="AR",IF(Inputs!$B$25=0,SQRT(Inputs!$B$8*F58/J58),(-Inputs!$B$25+SQRT(Inputs!$B$25^2+4*(1-Inputs!$B$25)*Inputs!$B$8*F58/J58))/(2*(1-Inputs!$B$25))),IF(B58="AD",Inputs!$B$8*F58/(2*J58),2*Inputs!$B$8*F58/J58)) -> 0.0041631936 | O58: =MIN(Inputs!$B$26,M58*L58) -> 0.0023504537 | P58: =MIN(Inputs!$B$26,O58*Inputs!$B$19) -> 0.023504537 | Q58: =MIN(O58,N58*Inputs!$B$21) -> 0.00020815968 | U58: =IF(COUNT(R58:T58)>0,"Published spec (+calc where blank)","Calculated (this workbook)") -> Calculated (this workbook) | V58: =IF(R58="",MAX(P58,W58),R58) -> 0.023504537 | W58: =IF(S58="",O58,S58) -> 0.0023504537 | X58: =IF(T58="",Q58,T58) -> 0.00020815968 | Y58: =IF(S58="","",IF(O58<S58,"Calc STRICTER (lower)","Calc more lenient (higher)")) | Z58: =IF(B58="XL","Hemizygous male AF (grpmax)","grpmax FAF95; check SAS, IndiGen, GenomeIndia") -> grpmax FAF95; check SAS, IndiGen, GenomeIndia
